<?xml version="1.0" ?>
<robot name="fura2a" xmlns:xacro="http://www.ros.org/wiki/xacro">

<xacro:include filename="$(find fura2a)/urdf/materials.xacro" />
<xacro:include filename="$(find fura2a)/urdf/fura2a.gazebo" />
<xacro:include filename="$(find fura2a)/urdf/ros2_control.xacro" />


<link name="base_link">
  <inertial>
    <origin xyz="-1.4655194516233777e-17 0.0 0.009896382619700488" rpy="0 0 0"/>
    <mass value="50"/>
    <inertia ixx="0.012198" iyy="0.012198" izz="0.024075" ixy="-0.0" iyz="0.0" ixz="0.0"/>
  </inertial>
  <visual>
    <origin xyz="0 0 0" rpy="0 0 0"/>
    <geometry>
      <mesh filename="file://$(find fura2a)/meshes/base_link.stl" scale="0.001 0.001 0.001"/>
    </geometry>
    <material name="CustomRed"/>
  </visual>
  <collision>
    <origin xyz="0 0 0" rpy="0 0 0"/>
    <geometry>
      <mesh filename="file://$(find fura2a)/meshes/base_link.stl" scale="0.001 0.001 0.001"/>
    </geometry>
  </collision>
</link>

<link name="column">
  <inertial>
    <origin xyz="1.0658141036401502e-16 0.0 0.062495742145380256" rpy="0 0 0"/>
    <mass value="50"/>
    <inertia ixx="0.014849" iyy="0.014849" izz="0.009632" ixy="0.0" iyz="0.0" ixz="0.0"/>
  </inertial>
  <visual>
    <origin xyz="-0.0 -0.0 -0.02" rpy="0 0 0"/>
    <geometry>
      <mesh filename="file://$(find fura2a)/meshes/column.stl" scale="0.001 0.001 0.001"/>
    </geometry>
    <material name="CustomYellow"/>
  </visual>
  <collision>
    <origin xyz="-0.0 -0.0 -0.02" rpy="0 0 0"/>
    <geometry>
      <mesh filename="file://$(find fura2a)/meshes/column.stl" scale="0.001 0.001 0.001"/>
    </geometry>
  </collision>
</link>

<!-- <link name="arm">
  <inertial>
    <origin xyz="0.037500000000000006 -2.220446049250313e-18 0.0062500000000000056" rpy="0 0 0"/>
    <mass value="0.07359375"/>
    <inertia ixx="2e-06" iyy="3.5e-05" izz="3.5e-05" ixy="-0.0" iyz="0.0" ixz="0.0"/>
  </inertial>
  <visual>
    <origin xyz="-0.0 -0.0 -0.145" rpy="0 0 0"/>
    <geometry>
      <mesh filename="file://$(find fura2a)/meshes/hollowed_arm.stl" scale="0.001 0.001 0.001"/>
    </geometry>
    <material name="CustomGreen"/>
  </visual>
  <collision>
    <origin xyz="-0.0 -0.0 -0.145" rpy="0 0 0"/>
    <geometry>
      <mesh filename="file://$(find fura2a)/meshes/fake_arm.stl" scale="0.001 0.001 0.001"/>
    </geometry>
  </collision>
</link> -->


<link name="arm">
  <inertial>
    <origin xyz="0.037500000000000006 -2.220446049250313e-18 0.0062500000000000056" rpy="0 0 0"/>
    <mass value="0.3"/>
    <inertia ixx="8.15286624e-06" iyy="1.42675159e-04" izz="1.42675159e-04" ixy="-0.0" iyz="0.0" ixz="0.0"/>
  </inertial>
  <visual>
    <origin xyz="-0.0 -0.0 -0.145" rpy="0 0 0"/>
    <geometry>
      <mesh filename="file://$(find fura2a)/meshes/hollowed_arm.stl" scale="0.001 0.001 0.001"/>
    </geometry>
    <material name="CustomGreen"/>
  </visual>
  <collision>
    <origin xyz="-0.0 -0.0 -0.145" rpy="0 0 0"/>
    <geometry>
      <mesh filename="file://$(find fura2a)/meshes/fake_arm.stl" scale="0.001 0.001 0.001"/>
    </geometry>
  </collision>
</link>
<link name="pendulum">
  <inertial>
    <origin xyz="0.0050000000000000044 -8.574075045622943e-18 -0.0675" rpy="0 0 0"/>
    <mass value="0.10597499999999999"/>
    <inertia ixx="0.000162" iyy="0.000162" izz="2e-06" ixy="0.0" iyz="-0.0" ixz="-0.0"/>
  </inertial>
  <visual>
    <origin xyz="-0.075 -0.0 -0.1575" rpy="0 0 0"/>
    <geometry>
      <mesh filename="file://$(find fura2a)/meshes/pendulum_down.stl" scale="0.001 0.001 0.001"/>
    </geometry>
    <material name="CustomBlue"/>
  </visual>
  <collision>
    <origin xyz="-0.075 0.0 -0.1575" rpy="0 0 0"/>
    <geometry>
      <mesh filename="file://$(find fura2a)/meshes/cuboid_pendulum.stl" scale="0.001 0.001 0.001"/>
    </geometry>
  </collision>
</link>

<joint name="base_column_joint" type="fixed">
  <origin xyz="0.0 0.0 0.02" rpy="0 0 0"/>
  <parent link="base_link"/>
  <child link="column"/>
</joint>

<joint name="arm_joint" type="continuous">
  <origin xyz="0.0 0.0 0.125" rpy="0 0 0"/>
  <parent link="column"/>
  <child link="arm"/>
  <axis xyz="0.0 0.0 1.0"/>
  <!-- <dynamics damping="0.0001"/> Added damping -->
</joint>

<joint name="pendulum_joint" type="continuous">
  <origin xyz="0.075 0.0 0.0125" rpy="0 0 0"/>
  <parent link="arm"/>
  <child link="pendulum"/>
  <axis xyz="1.0 0.0 0.0"/>
  <!-- <dynamics damping="0.0003"/> Added damping -->

</joint>


</robot>
